Workbook
Name Print_Area_MI: 'Equip Review 032310'!$B$2:$Z$12

Sheet LOC13
A1: ABS EQUIPMENT LEASING INC.
A2: FIXED ASSET LEDGER - LOCATION SUMMARY
B3: REVISED AS OF 10/24/13
E5: M | F5: included in Misc. Summary
J6: A | P6: B | Q6: C | R6: A + B + C | W6: RECONCILIATION TO F11 SCH | Z6: F 11 | AA6: Linked to sheets
A7: Asset | I7: Fiscal | J7: Total | L7: Book | M7: FMV | P7: ON | Q7: FORECAST | R7: TOTAL | U7: Orig | V7: FINAL | Z7: VARIANCE | AA7: Additions | AB7: Additions | AC7: Additions
A8: # | B8: Description | C8: Model | D8: Serial # | E8: M | F8: Location | G8: LOCATION 2 | H8: Bay | I8: Purch Yr. | J8: F13 Costs | K8: Depreciation | L8: Value | M8: ESTIMATE | N8: Active/Inactive | P8: DEPOSIT | Q8: SPEND | R8: COSTS | S8: Vendor | U8: PO # | V8: F11 | X8: F11 | Y8: F11 | Z8: TO F13 | AA8: F12 | AB8: F13 | AC8: F14
A9: 100 | B9: =+'100'!A7 -> FORESTLINE #1 | C9: =+'100'!A8 -> VECOMIL 563 5 AXIS CNC VERTICAL | D9: =+'100'!C7 -> 3051 | F9: =+'100'!B11 -> MISS | G9: 1495 | H9: 1495 | I9: 2004 | J9: =+'100'!R7 -> 1971035.5 | K9: =+'100'!S7 -> 1971035.5 | L9: =+J9-K9 -> 0 | M9: 1500000 | N9: A | O9: =+J9-K9-L9 -> -4.6566129e-10 | P9: =82000+347000 -> 429000 | Q9: =307000+82000 -> 389000 | R9: =+J9+P9+Q9 -> 2789035.5 | V9: 1122082.2 | W9: 100 | Z9: =+J9-V9 -> 848953.25 | AA9: =+'100'!V14 -> 440690.72
A10: 108 | B10: =+'108'!A7 -> SAN ROCCO - FUTURA 14 | C10: =+'108'!A9 -> HORIZONTAL BORING MILL | D10: =+'108'!C7 -> F07/6 | F10: =+'108'!B11 -> MISS | G10: 1495 | H10: 1495 | I10: 1994 | J10: =+'108'!R7 -> 1288891.3 | K10: =+'108'!S7 -> 1288891.3 | L10: =+J10-K10 -> 0 | M10: 875000 | N10: A | O10: =+J10-K10-L10 -> -2.3283064e-10 | R10: =+J10+P10+Q10 -> 1288891.3 | V10: 1288891.3 | W10: 108 | Z10: =+J10-V10 -> 0
A11: 117 | B11: TOSHIBA BTD-13F.R22 | D11: 144926 | F11: MISS | G11: 1495 | H11: 1495 | I11: ='117'!$Q$13 -> 2007 | J11: =+'117'!R7 -> 749420.97 | K11: =+'117'!S7 -> 749420.97 | L11: =+J11-K11 -> 0 | M11: 600000 | N11: A | O11: =+J11-K11-L11 -> 0 | R11: =+J11+P11+Q11 -> 749420.97 | V11: 749420.97 | W11: 117 | Z11: =+J11-V11 -> 0
A12: 118 | B12: TOSHIBA TMD - 16 | C12: CNC VBM | D12: 420165 | F12: MISS | G12: 1495 | H12: 1495 | I12: ='118'!$Q$13 -> 2007 | J12: =+'118'!R7 -> 691113.35 | K12: =+'118'!S7 -> 691113.35 | L12: =+J12-K12 -> 0 | M12: 500000 | N12: A | O12: =+J12-K12-L12 -> -1.1641532e-10 | R12: =+J12+P12+Q12 -> 691113.35 | V12: 691113.35 | W12: 118 | Z12: =+J12-V12 -> 0
A13: 119 | B13: TOSHIBA TUE-15 | C13: ='119'!$A$7 -> VBM | D13: 440376 | F13: MISS | G13: 1495 | H13: 1495 | I13: 2009 | J13: =+'119'!R7 -> 442044 | K13: =+'119'!S7 -> 442044 | L13: =+J13-K13 -> 0 | M13: 350000 | N13: A | O13: =+J13-K13-L13 -> 5.8207661e-11 | R13: =+J13+P13+Q13 -> 442044 | V13: 442044 | W13: 119 | Z13: =+J13-V13 -> 0
A14: 159 | B14: TOSHIBA BP-150.R22 #2 | C14: BP-150.R22 | D14: 130380 | F14: MISS | G14: 1495 | H14: 1495 | I14: 2009 | J14: =+'159'!R7 -> 935280.49 | K14: =+'159'!S7 -> 935280.49 | L14: =+J14-K14 -> 0 | M14: 750000 | N14: A | O14: =+J14-K14-L14 -> -1.1641532e-10 | R14: =+J14+P14+Q14 -> 935280.49 | V14: 935280.49 | W14: 144 | Z14: =+J14-V14 -> 0
A15: 164 | B15: TOSHIBA TMD-23 #1 | C15: VBM | D15: 420182 | F15: MISS | G15: 1495 | H15: 1495 | I15: 2009 | J15: =+'164'!R7 -> 897755.57 | K15: =+'164'!S7 -> 897755.57 | L15: =+J15-K15 -> 0 | M15: 800000 | N15: A | O15: =+J15-K15-L15 -> 1.1641532e-10 | R15: =+J15+P15+Q15 -> 897755.57 | V15: 892865.71 | W15: 159 | Z15: =+J15-V15 -> 4889.86
A16: 175 | B16: CRANE; STAHLKRANE; 7.5[t]; BRIDGE TYPE | D16: M0190435 | E16: M | F16: MISS | G16: 1495 | H16: 1495 | L16: =+J16-K16 -> 0 | N16: A | O16: =+J16-K16-L16 -> 0 | R16: =+J16+P16+Q16 -> 0 | V16: 0 | W16: 160 | Z16: =+J16-V16 -> 0
A17: 211 | B17: E-R MAIER VERTICAL BANDSAW | E17: M | F17: MISS | G17: 1495 | H17: 1495 | L17: =+J17-K17 -> 0 | M17: 500 | N17: A | O17: =+J17-K17-L17 -> 0 | R17: =+J17+P17+Q17 -> 0 | W17: 200 | Z17: =+J17-V17 -> 0
A18: 299 | B18: STYLINER SUPER STRINGER | C18: HAND MARKING HEAD | F18: MISS | G18: 1495 | H18: 1495 | I18: 2010 | J18: 9685 | L18: =+J18-K18 -> 9685 | M18: 6000 | N18: A | O18: =+J18-K18-L18 -> 0 | R18: =+J18+P18+Q18 -> 9685 | V18: 9685 | W18: 278 | Z18: =+J18-V18 -> 0
A19: 316 | B19: NOMURA | C19: HBM-HBA-110T-R3 | D19: 5380 | F19: MISS | G19: 1495 | H19: 1495 | I19: 2012 | J19: =495000+16300 -> 511300 | M19: =+J19 -> 511300 | R19: =+J19+P19+Q19 -> 511300 | W19: 296 | Z19: =+J19-V19 -> 511300 | AB19: 619412.89
G20: 1495 Total | M20: =SUBTOTAL(9,M9:M19) -> 5892800 | AB20: =SUBTOTAL(9,AB9:AB19) -> 619412.89
A21: 273 | B21: VIRGINIA CRANE DOUBLE GIRDER | C21: BRIDGE CRANE (50/10 TON) | D21: VC89-323 | F21: 3100 | G21: 3100 | I21: 2010 | J21: ='273'!C14 -> 120322.9 | L21: =+J21-K21 -> 120322.9 | M21: 100000 | N21: A | O21: =+J21-K21-L21 -> 0 | R21: =+J21+P21+Q21 -> 120322.9 | V21: 93679.4 | W21: 254 | Z21: =+J21-V21 -> 26643.5
A22: 295 | B22: SHAW BOX 40 TON CRANE | C22: GIRDER OVER BRIDGE 72 FT. | D22: 59-37500 | F22: 3100 | G22: 3100 | I22: 2011 | J22: =17257.87+17257.87+186009.78 -> 220525.52 | L22: =+J22-K22 -> 220525.52 | M22: 55000 | N22: A | O22: =+J22-K22-L22 -> 0 | R22: =+J22+P22+Q22 -> 220525.52 | V22: 34515.74 | W22: 274 | Z22: =+J22-V22 -> 186009.78
A23: 296 | B23: CRANE HOIST 30 TON & 15 AUXILARY | C23: IST LEASIING CORP | F23: 3100 | G23: 3100 | I23: 2010 | J23: 17500 | L23: =+J23-K23 -> 17500 | M23: 45000 | N23: A | O23: =+J23-K23-L23 -> 0 | R23: =+J23+P23+Q23 -> 17500 | V23: 17500 | W23: 275 | Z23: =+J23-V23 -> 0
A24: 301 | B24: WELDING ELECTRICAL | F24: 3100 | G24: 3100 | I24: 2011 | J24: 96028 | L24: =+J24-K24 -> 96028 | M24: 50000 | N24: A | O24: =+J24-K24-L24 -> 0 | R24: =+J24+P24+Q24 -> 96028 | V24: 96028 | W24: 280 | Z24: =+J24-V24 -> 0
A25: 302 | B25: COMPRESSOR | F25: 3100 | G25: 3100 | I25: 2011 | J25: 11773 | L25: =+J25-K25 -> 11773 | M25: 8000 | N25: A | O25: =+J25-K25-L25 -> 0 | R25: =+J25+P25+Q25 -> 11773 | V25: 11773 | W25: 281 | Z25: =+J25-V25 -> 0
A26: 303 | B26: WELDING STN FLOOR PLATES | F26: 3100 | G26: 3100 | I26: 2011 | J26: 200351 | L26: =+J26-K26 -> 200351 | M26: 200000 | N26: A | O26: =+J26-K26-L26 -> 0 | R26: =+J26+P26+Q26 -> 200351 | V26: 200351 | W26: 282 | Z26: =+J26-V26 -> 0
A27: 304 | B27: WELDING EQUIPMENT | F27: 3100 | G27: 3100 | I27: 2011 | J27: 153084 | L27: =+J27-K27 -> 153084 | M27: 100000 | N27: A | O27: =+J27-K27-L27 -> 0 | R27: =+J27+P27+Q27 -> 153084 | V27: 153084 | W27: 283 | Z27: =+J27-V27 -> 0
A28: 305 | B28: CRANES 3100 | F28: 3100 | G28: 3100 | I28: 2011 | J28: =120321+186009+51651+90550 -> 448531 | L28: =+J28-K28 -> 448531 | M28: 250000 | N28: A | O28: =+J28-K28-L28 -> 0 | R28: =+J28+P28+Q28 -> 448531 | V28: 448531 | W28: 284 | Z28: =+J28-V28 -> 0
A29: 719.2 | B29: LOCKERS WELD SHOP | F29: 3100 | G29: 3100 | I29: 2011 | J29: 2340 | L29: =+J29-K29 -> 2340 | M29: =+J29 -> 2340 | N29: A | O29: =+J29-K29-L29 -> 0 | R29: =+J29+P29+Q29 -> 2340 | V29: 2340 | W29: 709 | Z29: =+J29-V29 -> 0
A30: 827 | B30: DRIVE ROLL | C30: WELD SHOP' | F30: 3100 | G30: 3100 | I30: 2012 | J30: 32986 | M30: =+J30 -> 32986 | R30: =+J30+P30+Q30 -> 32986 | S30: PO-107807 | T30: RED-D-ARC | Z30: =+J30-V30 -> 32986
A31: 115 | B31: WELDING POSITIONER NEW | C31: 30-6 AB POSIT | D31: 15312X08-20 | F31: MISS | G31: 3100 | H31: 3100 | I31: 2009 | J31: ='115'!$R$7 -> 38496.5 | K31: ='115'!$S$7 -> 38496.5 | L31: =+J31-K31 -> 0 | M31: 8000 | N31: A | O31: =+J31-K31-L31 -> 7.2759576e-12 | R31: =+J31+P31+Q31 -> 38496.5 | V31: 19120.07 | W31: 115 | Z31: =+J31-V31 -> 19376.43
A32: 835 | B32: ARONSON WELDING POSITIONER (Gi200) | C32: G1200 | D32: 48131 | F32: MISS | G32: 3100 | H32: 3100 | J32: 261100 | M32: 261100
A33: 836 | B33: ARONSON WELDING POSITIONER (HD500) | C33: HD 500 | D33: 48315 | F33: MISS | G33: 3100 | H33: 3100 | J33: 165000 | M33: 165000
G34: 3100 Total | M34: =SUBTOTAL(9,M21:M33) -> 1277426 | AB34: =SUBTOTAL(9,AB21:AB33) -> 0
A35: MISC | B35: SEE MISC. SHEET | C35: M = SEE MISC. SHEET | E35: M | F35: 94-10 | G35: 94-10 | J35: =MISC!$S$7 -> 5916533.8 | K35: =MISC!$T$7 -> 4699006.8 | L35: =+J35-K35 -> 1217527 | M35: 300000 | O35: =+J35-K35-L35 -> 0 | R35: =+J35+P35+Q35 -> 5916533.8 | V35: 4886192.5 | Z35: =+J35-V35 -> 1030341.3
G36: 94-10 Total | M36: =SUBTOTAL(9,M35:M35) -> 300000 | AB36: =SUBTOTAL(9,AB35:AB35) -> 0
A37: 277 | B37: DELKEN TABLE CAPACITY 10 TON (WOTAN RAPID 2) | C37: DCN 150 ST | F37: BRAM | G37: BRAM | I37: 2005 | J37: ='277'!$R$7 -> 185377.28 | K37: ='277'!$S$7 -> 185377.28 | L37: =+J37-K37 -> 0 | M37: 150000 | O37: =+J37-K37-L37 -> 2.910383e-11 | R37: =+J37+P37+Q37 -> 185377.28 | V37: 185377.28 | W37: 259 | Z37: =+J37-V37 -> 0
A38: 309 | B38: RAVENSBURG LATHE | C38: KH 100 | D38: 9326 | F38: BRAM | G38: BRAM | I38: 2011 | J38: 90000 | L38: =+J38-K38 -> 90000 | M38: =+J38 -> 90000 | N38: A | O38: =+J38-K38-L38 -> 0 | R38: =+J38+P38+Q38 -> 90000 | V38: 90000 | W38: 289 | Z38: =+J38-V38 -> 0
A39: 310 | B39: RAVENSBURG LATHE | C39: KH 100 | D39: 9327 | F39: BRAM | G39: BRAM | I39: 2011 | J39: 90000 | L39: =+J39-K39 -> 90000 | M39: =+J39 -> 90000 | N39: A | O39: =+J39-K39-L39 -> 0 | R39: =+J39+P39+Q39 -> 90000 | V39: 90000 | W39: 290 | Z39: =+J39-V39 -> 0
A40: 502 | B40: =+'502'!A7 -> MANDELLI | C40: =+'502'!A8 -> M 8 | D40: =+'502'!C7 -> 7874 | F40: BRAM | G40: BRAM | I40: 2004 | J40: =+'502'!R7 -> 695116 | K40: =+'502'!S7 -> 695116 | L40: =+J40-K40 -> 0 | M40: 300000 | N40: A | O40: =+J40-K40-L40 -> 1.1641532e-10 | R40: =+J40+P40+Q40 -> 695116 | V40: 695116 | W40: 304 | Z40: =+J40-V40 -> 0
A41: 512 | B41: R 16 TOSHIBA 144725 | D41: 144725 | F41: BRAM | G41: BRAM | I41: 2005 | J41: =+'512'!R7 -> 855698.36 | K41: =+'512'!S7 -> 855698.36 | L41: =+J41-K41 -> 0 | M41: 450000 | N41: A | O41: =+J41-K41-L41 -> -2.3283064e-10 | R41: =+J41+P41+Q41 -> 855698.36 | V41: 860698.36 | W41: 500 | Z41: =+J41-V41 -> -5000
...

Sheet Annual Depr.
A1: ABS EQUIPMENT LEASING INC.
A2: Select Equipment List
A3: Source: F 2009 Fixed Asset Summary
S4: Total | U4: Book
A5: Description | B5: Asset # | C5: Serial # | S5: Costs | T5: Depr. | U5: Value
S7: =+#REF! -> #REF! | T7: =+-C34 -> #REF! | U7: =+S7-T7 -> #REF!
B11: Asset #
A13: Purchased Year Ending | C13: Total | D13: 1994 | E13: misc | F13: 1995 | G13: 1996 | H13: 1997 | I13: 1998 | J13: 1999 | K13: 2000 | L13: 2001 | M13: 2002 | N13: 2003 | O13: 2004 | P13: 2005 | Q13: 2006 | R13: 2007 | S13: 2008 | T13: 2009 | U13: 2010
A14: Purchases (Fiscal Yr.)
A15: check | D15: Segal | E15: ABS
A16: Depreciation | B16: 1994 | C16: #REF!
B17: 1995 | C17: #REF!
B18: 1996 | C18: #REF!
B19: 1997 | C19: #REF!
B20: 1998 | C20: #REF!
B21: 1999 | C21: #REF!
B22: 2000 | C22: #REF! | D22: -539044 | E22: -2400321.2
B23: 2001 | C23: #REF! | D23: -785174 | E23: -2739563.9
B24: 2002 | C24: #REF! | D24: -1683282 | E24: -2975686.1
B25: 2003 | C25: #REF! | D25: -1933030 | E25: -3044242.8
B26: 2004 | C26: #REF! | D26: -2164488.4 | E26: -3127839
B27: 2005 | C27: #REF! | D27: -2548243 | E27: -3210482.9
B28: 2006 | C28: #REF! | D28: -2640430 | E28: -3164727.2
B29: 2007 | C29: #REF! | D29: -2680139 | E29: -2960489
B30: 2008 | C30: #REF! | D30: -3239313 | E30: -3386109.1
B31: 2009 | C31: #REF! | D31: -3886113 | E31: -3937819.3
A32: To April 30th, 2010 | B32: 2010 | C32: #REF!
A34: ST | C34: =SUM(C16:C33) -> #REF! | D34: =SUM(D16:D33) -> -22099256 | E34: =SUM(E16:E33) -> -30947281
A36: Total depr. As per summary | C36: 40949363
A37: Variance | C37: =SUM(C34:C36) -> #REF!
O39: =SUM(F32:F39) -> 0

Sheet templ
A1: ABS EQUIPMENT LEASING INC. | O1: "Do not add rows or columns"
A2: Equipment List
A3: Source: F 2014 Fixed Asset Summary
R4: Total | T4: Book
A5: Description | B5: Asset # | C5: Serial # | R5: Costs | S5: Depr. | T5: Value
R7: =+C14 -> 0 | S7: =+-C40 -> 0 | T7: =+R7-S7 -> 0
A11: Location:
A13: Purchased Year Ending | C13: Total | D13: 1994 | E13: 1995 | F13: 1996 | G13: 1997 | H13: 1998 | I13: 1999 | J13: 2000 | K13: 2001 | L13: 2002 | M13: 2003 | N13: 2004 | O13: 2005 | P13: 2006 | Q13: 2007 | R13: 2008 | S13: 2009 | T13: 2010 | U13: 2011 | V13: 2012 | W13: 2013 | X13: 2014 | Y13: 2015
A14: Purchases (Fiscal Yr.) | C14: =SUM(D14:X14) -> 0 | D14: 0 | E14: 0 | F14: 0 | G14: 0 | H14: 0 | I14: 0 | J14: 0 | K14: 0 | L14: 0 | M14: 0
A16: Depreciation | B16: 1994 | C16: =-SUM(D16:X16) -> 0 | D16: =+D$14/7/2 -> 0
B17: 1995 | C17: =-SUM(D17:X17) -> 0 | D17: =+D$14/7 -> 0 | E17: =+E$14/7/2 -> 0
B18: 1996 | C18: =-SUM(D18:X18) -> 0 | D18: =+D17 -> 0 | E18: =+E$14/7 -> 0 | F18: =+F$14/7/2 -> 0
B19: 1997 | C19: =-SUM(D19:X19) -> 0 | D19: =+D18 -> 0 | E19: =+E18 -> 0 | F19: =+F$14/7 -> 0 | G19: =+G$14/7/2 -> 0
B20: 1998 | C20: =-SUM(D20:X20) -> 0 | D20: =+D19 -> 0 | E20: =+E19 -> 0 | F20: =+F19 -> 0 | G20: =+G$14/7 -> 0 | H20: =+H$14/7/2 -> 0
B21: 1999 | C21: =-SUM(D21:X21) -> 0 | D21: =+D20 -> 0 | E21: =+E20 -> 0 | F21: =+F20 -> 0 | G21: =+G20 -> 0 | H21: =+H$14/7 -> 0 | I21: =+I$14/7/2 -> 0
B22: 2000 | C22: =-SUM(D22:X22) -> 0 | D22: =+D21 -> 0 | E22: =+E21 -> 0 | F22: =+F21 -> 0 | G22: =+G21 -> 0 | H22: =+H21 -> 0 | I22: =+I$14/7 -> 0 | J22: =+J$14/7/2 -> 0
B23: 2001 | C23: =-SUM(D23:X23) -> 0 | D23: =+D$14/7/2 -> 0 | E23: =+E22 -> 0 | F23: =+F22 -> 0 | G23: =+G22 -> 0 | H23: =+H22 -> 0 | I23: =+I22 -> 0 | J23: =+J$14/7 -> 0 | K23: =+K$14/7/2 -> 0
B24: 2002 | C24: =-SUM(D24:X24) -> 0 | E24: =+E$14/7/2 -> 0 | F24: =+F23 -> 0 | G24: =+G23 -> 0 | H24: =+H23 -> 0 | I24: =+I23 -> 0 | J24: =+J23 -> 0 | K24: =+K$14/7 -> 0 | L24: =+L$14/7/2 -> 0
B25: 2003 | C25: =-SUM(D25:X25) -> 0 | F25: =+F$14/7/2 -> 0 | G25: =+G24 -> 0 | H25: =+H24 -> 0 | I25: =+I24 -> 0 | J25: =+J24 -> 0 | K25: =+K24 -> 0 | L25: =+L$14/7 -> 0 | M25: =+M$14/7/2 -> 0
B26: 2004 | C26: =-SUM(D26:X26) -> 0 | G26: =+G$14/7/2 -> 0 | H26: =+H25 -> 0 | I26: =+I25 -> 0 | J26: =+J25 -> 0 | K26: =+K25 -> 0 | L26: =+L25 -> 0 | M26: =+M$14/7 -> 0 | N26: =+N$14/7/2 -> 0
B27: 2005 | C27: =-SUM(D27:X27) -> 0 | H27: =+H$14/7/2 -> 0 | I27: =+I26 -> 0 | J27: =+J26 -> 0 | K27: =+K26 -> 0 | L27: =+L26 -> 0 | M27: =+M26 -> 0 | N27: =+N$14/7 -> 0 | O27: =+O$14/7/2 -> 0
B28: 2006 | C28: =-SUM(D28:X28) -> 0 | I28: =+I$14/7/2 -> 0 | J28: =+J27 -> 0 | K28: =+K27 -> 0 | L28: =+L27 -> 0 | M28: =+M27 -> 0 | N28: =+N27 -> 0 | O28: =+O$14/7 -> 0 | P28: =+P$14/7/2 -> 0
B29: 2007 | C29: =-SUM(D29:X29) -> 0 | J29: =+J$14/7/2 -> 0 | K29: =+K28 -> 0 | L29: =+L28 -> 0 | M29: =+M28 -> 0 | N29: =+N28 -> 0 | O29: =+O28 -> 0 | P29: =+P$14/7 -> 0 | Q29: =+Q$14/7/2 -> 0
B30: 2008 | C30: =-SUM(D30:X30) -> 0 | K30: =+K$14/7/2 -> 0 | L30: =+L29 -> 0 | M30: =+M29 -> 0 | N30: =+N29 -> 0 | O30: =+O29 -> 0 | P30: =+P29 -> 0 | Q30: =+Q$14/7 -> 0 | R30: =+R$14/7/2 -> 0
B31: 2009 | C31: =-SUM(D31:X31) -> 0 | L31: =+L$14/7/2 -> 0 | M31: =+M30 -> 0 | N31: =+N30 -> 0 | O31: =+O30 -> 0 | P31: =+P30 -> 0 | Q31: =+Q30 -> 0 | R31: =+R$14/7 -> 0 | S31: =+S$14/7/2 -> 0
A32: To April 30th, 2010 | B32: 2010 | C32: =-SUM(D32:X32) -> 0 | M32: =+M$14/7/2 -> 0 | N32: =+N31 -> 0 | O32: =+O31 -> 0 | P32: =+P31 -> 0 | Q32: =+Q31 -> 0 | R32: =+R31 -> 0 | S32: =+S$14/7 -> 0 | T32: =+T$14/7/2 -> 0
B33: 2011 | C33: =-SUM(D33:X33) -> 0 | N33: =+N$14/7/2 -> 0 | O33: =+O32 -> 0 | P33: =+P32 -> 0 | Q33: =+Q32 -> 0 | R33: =+R32 -> 0 | S33: =+S32 -> 0 | T33: =+T$14/7 -> 0 | U33: =+U$14/7/2 -> 0
B34: 2012 | C34: =-SUM(D34:X34) -> 0 | O34: =+O$14/7/2 -> 0 | P34: =+P33 -> 0 | Q34: =+Q33 -> 0 | R34: =+R33 -> 0 | S34: =+S33 -> 0 | T34: =+T$14/7 -> 0 | U34: =+U$14/7 -> 0 | V34: =+V$14/7/2 -> 0
B35: 2013 | C35: =-SUM(D35:X35) -> 0
B36: 2014 | C36: =-SUM(D36:X36) -> 0
B37: 2015
A40: ST | B40: =SUM(D40:X40) -> 0 | C40: =SUM(C16:C39) -> 0 | D40: =-SUM(D16:D39)+D14 -> 0 | E40: =-SUM(E16:E39)+E14 -> 0 | F40: =-SUM(F16:F39)+F14 -> 0 | G40: =-SUM(G16:G39)+G14 -> 0 | H40: =-SUM(H16:H39)+H14 -> 0 | I40: =-SUM(I16:I39)+I14 -> 0 | J40: =-SUM(J16:J39)+J14 -> 0 | K40: =-SUM(K16:K39)+K14 -> 0 | ... X40: =-SUM(X16:X39)+X14 -> 0
A42: Net Book Value | C42: =+C14+C40 -> 0
N45: =SUM(E32:E45) -> 0

Sheet SUMMARY
A1: ABS EQUIPMENT LEASING INC. | F1: 1490 A
A2: FIXED ASSET LEDGER | F2: 1490 B | I2: LINKED | J2: LINKED TO DET SHEET
B3: REVISED AS OF Jul 17, 2024 | J3: VALUE UPDATED TO F13
B4: NEW FILE FOR F 25 | J4: IN MISC SUMMARY | X4: MAY NOT
E5: M | F5: included in Misc. Summary | X5: BE RELAVENT | AB5: PAMA
I6: A | O6: B | P6: C | Q6: A + B + C | U6: RECONCILIATION TO F11 SCH | X6: F 11 | Y6: Linked to sheets | Z6: Linked to sheets | AA6: Linked to sheets | AB6: F13 | AC6: Linked to sheets | AH6: Linked to sheets | AI6: Linked to sheets | AK6: F16 ABSEL | AL6: F14 ABSEL | AM6: F15 ABSM | AP6: Linked to sheets | AR6: Linked to sheets | AT6: Linked to sheets | AV6: Linked to sheets | AX6: Linked to sheets | AZ6: Linked to sheets | BB6: Linked to sheets | BD6: Linked to sheets
A7: Asset | H7: Fiscal | I7: Total | K7: Book | L7: FMV | M7: Active/ Inactive | O7: ON | P7: FORECAST | Q7: TOTAL | S7: Orig | T7: FINAL BEG | X7: VARIANCE | Y7: Additions | Z7: Additions | AA7: Additions | AB7: PAMA | AC7: Additions | AH7: Additions | AI7: Additions | AK7: DEPOSIT TO | AL7: DEPOSIT TO | AM7: DEPOSIT TO | AP7: Additions | AR7: Additions | AT7: Additions | AV7: Additions | AX7: Additions | AZ7: Additions | BB7: Additions | BD7: Additions
A8: # | B8: Machine Name | C8: Model | D8: Serial # | E8: M | F8: Location | G8: Bay | H8: Purch Yr. | I8: Costs to Date | J8: Depreciation | K8: Value | L8: ESTIMATE | O8: DEPOSIT | P8: SPEND | Q8: COSTS | R8: Vendor | S8: PO # | T8: F11 | V8: F11 | W8: F11 | X8: TO F13 | Y8: F11 | Z8: F12 | AA8: F13 | AB8: ALLOCATION | AC8: F14 | AD8: NOTES | AE8: DEPRECIATION | AF8: BOOK VALUE | AH8: F15 | AI8: F16 | AJ8: NOTES | AK8: VENDOR | AL8: VENDOR | AM8: VENDOR | AP8: F17 | AR8: F18 | AT8: F19 | AV8: F20 | AX8: F21 | AZ8: F22 | BB8: F23 | BD8: F24
A9: 100 | B9: FORESTLINE #1 | C9: =+'100'!A8 -> VECOMIL 563 5 AXIS CNC VERTICAL | D9: 3051 | F9: MISS | G9: 1495 | H9: 2004 | I9: ='100'!C14 -> 1971035.5 | J9: =+'100'!S7 -> 1971035.5 | K9: =+I9-J9 -> 0 | L9: 2000000 | M9: A | N9: =+I9-J9-K9 -> -4.6566129e-10 | O9: =82000+347000 -> 429000 | P9: =307000+82000 -> 389000 | Q9: =+I9+O9+P9 -> 2789035.5 | T9: =544455 -> 544455 | U9: 100 | X9: =+I9-T9 -> 1426580.5 | Y9: ='100'!U14 -> 33173 | Z9: =+'100'!V14 -> 440690.72 | AA9: ='100'!W14 -> 37505.37 | AC9: ='100'!X14 -> 902360.38 | AE9: ='100'!S7 -> 1971035.5 | AF9: ='100'!T7 -> 0 | AH9: ='100'!Y14 -> 12851.4
A10: 101 | B10: MONTI FT 50 TG ( PURCH - ALESA MONTI) | C10: FT50TG | D10: 293/05.95 | F10: MISS | G10: ='101'!$C$11 -> C2 | H10: ='101'!$F$13 -> 1996 | I10: =+'101'!R7 -> 970993.94 | J10: =+'101'!S7 -> 825242.42 | K10: =+I10-J10 -> 145751.52 | L10: 200000 | M10: A | N10: =+I10-J10-K10 -> 0 | Q10: =+I10+O10+P10 -> 970993.94 | T10: 661741.31 | U10: 101 | X10: =+I10-T10 -> 309252.63 | AA10: ='101'!W14 -> 0 | AC10: ='101'!X15 -> 0 | AH10: ='101'!$Y$14 -> 0 | AV10: ='101'!AD14 -> 62123.56 | AX10: ='101'!AE14 -> 247129.07
A11: 102 | B11: FORESTLINE #2 | C11: FORESTLINE RETROFIT | D11: 3052 | F11: DUNDALK | H11: 2004 | I11: ='102'!R7 -> 560665.7 | J11: =+'102'!S7 -> 560665.7 | K11: =+I11-J11 -> 0 | L11: 500000 | M11: I | N11: =+I11-J11-K11 -> -1.1641532e-10 | Q11: =+I11+O11+P11 -> 560665.7 | T11: =T9 -> 544455 | U11: 102 | X11: =+I11-T11 -> 16210.7 | AA11: ='102'!W14 -> 0 | AC11: ='102'!X14 -> 0 | AD11: IN STORAGE | AH11: ='102'!$Y$14 -> 16211.08
A12: 103 | B12: PAMA SPEEDRAM # 3 INCL TBL | C12: BONETTI RETROFIT | D12: 33C-7168 | F12: BURL 1 | G12: 1601 | H12: ='103'!$I$13 -> 1999 | I12: =+'103'!R7 -> 3824420.5 | J12: =+'103'!S7 -> 3802179.5 | K12: =+I12-J12 -> 22241.024 | L12: 2500000 | M12: A | N12: =+I12-J12-K12 -> 0 | O12: 533000 | P12: 1505000 | Q12: =+I12+O12+P12 -> 5862420.5 | T12: 1307028.3 | U12: 103 | X12: =+I12-T12 -> 2517392.3 | AA12: ='103'!W14 -> 77000 | AB12: 77000 | AC12: ='103'!X14 -> 0 | AD12: TSF 1115008 | AH12: ='103'!$Y$14 -> 0 | AI12: ='103'!Z14 -> 2416440.4 | AL12: =66325+560822+139559+182181 -> 948887 | AM12: =26232.76+84780+193903.8+152604 -> 457520.56 | BD12: ='103'!AH14 -> 23951.88
A13: 104 | B13: PAMA CENTER 110 PO 113295 | C13: 5 AXIS | D13: 7357 | F13: JL | H13: ='104'!$D$13 -> 1994 | I13: =+'104'!R7 -> 2069204.1 | J13: =+'104'!S7 -> 2069204.1 | K13: =+I13-J13 -> 0 | L13: 1500000 | M13: A | N13: =+I13-J13-K13 -> -2.3283064e-10 | O13: 274000 | P13: 718000 | Q13: =+I13+O13+P13 -> 3061204.1 | T13: 783833.82 | U13: 104 | X13: =+I13-T13 -> 1285370.3 | AB13: 0 | AC13: ='104'!X14 -> 0 | AD13: TSF 1115008 | AH13: ='104'!$Y$14 -> 1366692.1 | AL13: =117808+224914+73270+80646 -> 496638 | AP13: =+'104'!AA14 -> -81321.82
A14: 105 | B14: WOTAN RAPID 2 | D14: 68142 | F14: MISS | G14: ='105'!$C$11 -> B4 | H14: ='105'!$M$13 -> 2003 | I14: =+'105'!R7 -> 827862.17 | J14: =+'105'!S7 -> 827862.17 | K14: =+I14-J14 -> 0 | L14: 450000 | M14: A | N14: =+I14-J14-K14 -> 1.1641532e-10 | Q14: =+I14+O14+P14 -> 827862.17 | T14: 743479.62 | U14: 105 | X14: =+I14-T14 -> 84382.55 | AC14: ='105'!X14 -> 0 | AH14: ='105'!$Y$14 -> 0
A15: 106 | B15: WOTAN 5 - Rapid 5P | C15: =+'106'!A8 -> CNC W/CNC A.B.840 D | D15: =+'106'!C7 -> 67019 | F15: =+'106'!B11 -> MISS | G15: ='106'!$C$11 -> A3 | H15: 2002 | I15: =+'106'!R7 -> 985457.86 | J15: =+'106'!S7 -> 984734.75 | K15: =+I15-J15 -> 723.10714 | L15: 750000 | M15: A | N15: =+I15-J15-K15 -> 0 | Q15: =+I15+O15+P15 -> 985457.86 | T15: 982083.36 | U15: 106 | X15: =+I15-T15 -> 3374.5 | AH15: ='106'!$Y$14 -> 0 | AT15: =+'106'!AC14 -> 3374.5
A16: 107 | B16: WOTAN RAPID 6 | C16: CNC HBM | D16: 65027 | F16: BURL 1 | G16: 1601 | H16: ='107'!$K$13 -> 2001 | I16: =+'107'!R7 -> 1785899.9 | J16: =+'107'!S7 -> 1682124.8 | K16: =+I16-J16 -> 103775.19 | L16: 1500000 | M16: A | N16: =+I16-J16-K16 -> 0 | Q16: =+I16+O16+P16 -> 1785899.9 | T16: 1628901 | U16: 107 | X16: =+I16-T16 -> 156998.98 | AH16: ='107'!$Y$14 -> 0 | AP16: =+'107'!AA14 -> 10468.74 | AR16: =+'107'!AB14 -> 22283.16 | AX16: ='107'!AE14 -> 24951.91 | AZ16: ='107'!AF14 -> 25584.97 | BB16: ='107'!AG14 -> 73710.2
A17: 108 | B17: =+'108'!A7 -> SAN ROCCO - FUTURA 14 | C17: =+'108'!A9 -> HORIZONTAL BORING MILL | D17: =+'108'!C7 -> F07/6 | F17: =+F11 -> DUNDALK | G17: 1495 | H17: 1994 | I17: =+'108'!R7 -> 1288891.3 | J17: =+'108'!S7 -> 1288891.3 | K17: =+I17-J17 -> 0 | L17: 875000 | M17: A | N17: =+I17-J17-K17 -> -2.3283064e-10 | Q17: =+I17+O17+P17 -> 1288891.3 | T17: 1288891.3 | U17: 108 | X17: =+I17-T17 -> 0 | AH17: ='108'!$Y$14 -> 0
A18: 110 | B18: NOT IN USE - SOLD | L18: =+I18 -> 0 | M18: I | S18: 645516
A19: 111 | B19: TOSHIBA BSF - 150B #1 | D19: 520443 | F19: MISS | G19: ='111'!$C$11 -> A2 | H19: ='111'!$J$13 -> 2000 | I19: =+'111'!R7 -> 2296413.2 | J19: ='111'!S7 -> 2245293.5 | K19: =+I19-J19 -> 51119.653 | L19: 1300000 | M19: A | N19: =+I19-J19-K19 -> 0 | Q19: =+I19+O19+P19 -> 2296413.2 | T19: 2216893.7 | U19: 111 | X19: =+I19-T19 -> 79519.46 | AH19: ='111'!$Y$14 -> 0 | AZ19: ='111'!AF14 -> 79519.46
A20: 112 | B20: =+'112'!A7 -> TOSHIBA BTD-110 - R 16 | C20: =+'112'!A8 -> HB&M | D20: =+'112'!C7 -> 143601 | F20: =+'112'!B11 -> MISS | G20: ='112'!$C$11 -> C1 | H20: 1997 | I20: =+'112'!R7 -> 668543.53 | J20: =+'112'!S7 -> 668543.53 | K20: =+I20-J20 -> 0 | L20: 285000 | M20: A | N20: =+I20-J20-K20 -> 0 | Q20: =+I20+O20+P20 -> 668543.53 | T20: 668543.53 | U20: 112 | X20: =+I20-T20 -> 0 | AH20: ='112'!$Y$14 -> 0
A21: 113 | B21: =+'113'!A7 -> Toshiba BTD 200QF | C21: =+'113'!A8 -> HB&M | D21: 144237 | F21: =+'113'!B11 -> MISS | G21: C1 | H21: 2001 | I21: =+'113'!R7 -> 685302.63 | J21: =+'113'!S7 -> 685302.63 | K21: =+I21-J21 -> 0 | L21: 375000 | M21: A | N21: =+I21-J21-K21 -> -1.1641532e-10 | Q21: =+I21+O21+P21 -> 685302.63 | T21: 685302.63 | U21: 113 | X21: =+I21-T21 -> 0 | AH21: ='113'!$Y$14 -> 0
A22: 115 | B22: WELDING POSITIONER NEW | C22: 30-6 AB POSIT | D22: 15312X08-20 | F22: 3100 | G22: 3100 | H22: 2009 | I22: ='115'!$R$7 -> 38496.5 | J22: ='115'!S7 -> 38496.5 | K22: =+I22-J22 -> 0 | L22: 8000 | M22: A | N22: =+I22-J22-K22 -> 7.2759576e-12 | Q22: =+I22+O22+P22 -> 38496.5 | T22: 19120.07 | U22: 115 | X22: =+I22-T22 -> 19376.43 | AH22: ='115'!$Y$14 -> 0 | AI22: ='115'!$Z$14 -> 19376.43
A23: 117 | B23: TOSHIBA BTD-13F.R22 | D23: 144926 | F23: MISS | G23: 1495 | H23: ='117'!$Q$13 -> 2007 | I23: =+'117'!R7 -> 749420.97 | J23: =+'117'!S7 -> 749420.97 | K23: =+I23-J23 -> 0 | L23: 600000 | M23: A | N23: =+I23-J23-K23 -> 0 | Q23: =+I23+O23+P23 -> 749420.97 | T23: 749420.97 | U23: 117 | X23: =+I23-T23 -> 0 | AH23: ='117'!$Y$14 -> 0
A24: 118 | B24: TOSHIBA TMD - 16 | C24: CNC VBM | D24: 420165 | F24: MISS | G24: 1495 | H24: ='118'!$Q$13 -> 2007 | I24: =+'118'!R7 -> 691113.35 | J24: =+'118'!S7 -> 691113.35 | K24: =+I24-J24 -> 0 | L24: 500000 | M24: A | N24: =+I24-J24-K24 -> -1.1641532e-10 | Q24: =+I24+O24+P24 -> 691113.35 | T24: 691113.35 | U24: 118 | X24: =+I24-T24 -> 0 | AH24: ='118'!$Y$14 -> 0
A25: 119 | B25: TOSHIBA TUE-15 | C25: ='119'!$A$7 -> VBM | D25: 440376 | F25: MISS | G25: 1495 | H25: 2009 | I25: =+'119'!R7 -> 442044 | J25: =+'119'!S7 -> 442044 | K25: =+I25-J25 -> 0 | L25: 350000 | M25: A | N25: =+I25-J25-K25 -> 5.8207661e-11 | Q25: =+I25+O25+P25 -> 442044 | T25: 442044 | U25: 119 | X25: =+I25-T25 -> 0 | AH25: ='119'!$Y$14 -> 0
A26: 122 | B26: =+'122'!A7 -> TOSHIBA BP 110 | C26: =+'122'!A8 -> HORIZONTAL PLANER TYPE | D26: =+'122'!C7 -> 130255 | F26: =+'122'!B11 -> MISS | G26: ='122'!$C$11 -> C2 | H26: 1998 | I26: =+'122'!R7 -> 583938.71 | J26: =+'122'!S7 -> 583938.71 | K26: =+I26-J26 -> 0 | L26: 300000 | M26: A | N26: =+I26-J26-K26 -> 0 | Q26: =+I26+O26+P26 -> 583938.71 | T26: 579784.84 | U26: 122 | X26: =+I26-T26 -> 4153.87 | AI26: =+'122'!Z14 -> 4153.87
A27: 124 | B27: DAEWOO ACE V850 | C27: ACE V850 | D27: V850075 | F27: MISS | G27: ='124'!$C$11 -> C2 | H27: ='124'!$H$13 -> 1998 | I27: =+'124'!R7 -> 342161.39 | J27: =+'124'!S7 -> 342161.39 | K27: =+I27-J27 -> 0 | L27: 75000 | M27: A | N27: =+I27-J27-K27 -> 0 | Q27: =+I27+O27+P27 -> 342161.39 | T27: 342161.39 | U27: 124 | X27: =+I27-T27 -> 0
A28: 126 | B28: =+'126'!A7 -> TOSHIBA BF-130B | C28: HB & M | D28: =+'126'!C7 -> 510658 | F28: =+'126'!B11 -> MISS | G28: ='126'!$C$11 -> A2 | H28: 1999 | I28: =+'126'!R7 -> 1239553.1 | J28: =+'126'!S7 -> 1239553.1 | K28: =+I28-J28 -> 0 | L28: 750000 | M28: A | N28: =+I28-J28-K28 -> -4.6566129e-10 | Q28: =+I28+O28+P28 -> 1239553.1 | T28: 1239553.1 | U28: 126 | X28: =+I28-T28 -> 0
A29: 128 | B29: TOSHIBA MPC #2 | C29: 3680B | D29: 910428 | F29: MISS | G29: ='128'!$C$11 -> A2 | H29: ='128'!$K$13 -> 2001 | I29: ='128'!R7 -> 2553028.6 | J29: ='128'!S7 -> 2553028.6 | K29: =+I29-J29 -> 0 | L29: 1400000 | M29: A | N29: =+I29-J29-K29 -> 0 | Q29: =+I29+O29+P29 -> 2553028.6 | T29: 2553028.6 | U29: 127 | V29: 159378.26 | W29: SOLD | X29: =+I29-T29 -> 0
A30: 133 | B30: SAFOP LATHE | C30: HT-850/CNC | D30: 3281 | F30: MISS | G30: ='133'!$C$11 -> B4 | H30: ='133'!$I$13 -> 1999 | I30: =+'133'!R7 -> 904845.26 | J30: =+'133'!S7 -> 904845.26 | K30: =+I30-J30 -> 0 | L30: 400000 | M30: A | N30: =+I30-J30-K30 -> 0 | Q30: =+I30+O30+P30 -> 904845.26 | T30: 885890.26 | U30: 128 | X30: =+I30-T30 -> 18955 | AH30: ='133'!Y14 -> 18955
A31: 141 | B31: KURAKI KBT-13-A | D31: 8172 | F31: MISS | G31: C3 | H31: 2006 | I31: =+'141'!R7 -> 858315.66 | J31: =+'141'!S7 -> 849327.09 | K31: =+I31-J31 -> 8988.5714 | L31: 625000 | M31: A | N31: =+I31-J31-K31 -> 0 | Q31: =+I31+O31+P31 -> 858315.66 | T31: 846875.66 | U31: 133 | X31: =+I31-T31 -> 11440 | BB31: ='141'!AG14 -> 11440
A32: 142 | B32: KURAKI KBT-13E-A | D32: 8189 | F32: MISS | G32: C3 | H32: 2007 | I32: =+'142'!R7 -> 900877.47 | J32: =+'142'!S7 -> 900877.47 | K32: =+I32-J32 -> 0 | L32: 675000 | M32: A | N32: =+I32-J32-K32 -> 0 | Q32: =+I32+O32+P32 -> 900877.47 | T32: 900877.47 | U32: 141 | X32: =+I32-T32 -> 0
A33: 144 | B33: BERTHIEZ TMM 250/315 | C33: TMM | F33: BUR -1601 | H33: 2002 | I33: =+'144'!R7 -> 2348919 | J33: =+'144'!S7 -> 1407030.7 | K33: =+I33-J33 -> 941888.24 | L33: 2000000 | M33: A | N33: =+I33-J33-K33 -> 0 | Q33: =+I33+O33+P33 -> 2348919 | T33: 1093866.1 | U33: 142 | X33: =+I33-T33 -> 1255052.9 | AX33: ='144'!AE14 -> 342005.64 | AZ33: ='144'!AF14 -> 68912.88 | BB33: ='144'!AG14 -> 400783.29 | BD33: ='144'!AH14 -> 443351.06
A34: 158 | B34: MAZAK VARIAXIS 730-5X II | D34: 211296 | F34: John Lucas - Burlington | G34: B3 | H34: 2009 | I34: =+'158'!R7 -> 612727 | J34: =+'158'!S7 -> 612727 | K34: =+I34-J34 -> 0 | L34: 400000 | M34: A | N34: =+I34-J34-K34 -> 0 | Q34: =+I34+O34+P34 -> 612727 | T34: 612727 | U34: 143 | X34: =+I34-T34 -> 0
A35: 159 | B35: TOSHIBA BP-150.R22 #2 | C35: BP-150.R22 | D35: 130380 | F35: MISS | G35: 1495 | H35: 2009 | I35: =+'159'!R7 -> 935280.49 | J35: =+'159'!S7 -> 935280.49 | K35: =+I35-J35 -> 0 | L35: 750000 | M35: A | N35: =+I35-J35-K35 -> -1.1641532e-10 | Q35: =+I35+O35+P35 -> 935280.49 | T35: 935280.49 | U35: 144 | X35: =+I35-T35 -> 0
A36: 160 | B36: MAZAK VBM | C36: ='160'!$A$8 -> E1060V/B | D36: ='160'!$C$7 -> 198546 | F36: =+F34 -> John Lucas - Burlington | G36: B1 | H36: 2008 | I36: =+'160'!R7 -> 1063805.7 | J36: ='160'!S7 -> 1063805.7 | K36: =+I36-J36 -> 0 | L36: 825000 | M36: A | N36: =+I36-J36-K36 -> 2.3283064e-10 | Q36: =+I36+O36+P36 -> 1063805.7 | T36: 1006718 | U36: 158 | X36: =+I36-T36 -> 57087.73 | AA36: ='160'!W14 -> 57087.73
A37: 164 | B37: TOSHIBA TMD-23 #1 | C37: VBM | D37: 420182 | F37: MISS | G37: 1495 | H37: 2009 | I37: =+'164'!R7 -> 897755.57 | J37: =+'164'!S7 -> 897755.57 | K37: =+I37-J37 -> 0 | L37: 800000 | M37: A | N37: =+I37-J37-K37 -> 1.1641532e-10 | Q37: =+I37+O37+P37 -> 897755.57 | T37: 892865.71 | U37: 159 | X37: =+I37-T37 -> 4889.86 | Z37: ='164'!V14 -> 4889.86 | AA37: ='164'!W14 -> 0
A38: 175 | B38: CRANE; STAHLKRANE; 7.5[t]; BRIDGE TYPE | D38: M0190435 | E38: M | F38: MISS | G38: 1490-C2 | K38: =+I38-J38 -> 0 | M38: A | N38: =+I38-J38-K38 -> 0 | Q38: =+I38+O38+P38 -> 0 | T38: 0 | U38: 160 | X38: =+I38-T38 -> 0
A39: 176 | B39: CRANE; SOS; 5[t]; BRIDGE TYPE | E39: M | F39: MISS | K39: =+I39-J39 -> 0 | M39: A | N39: =+I39-J39-K39 -> 0 | Q39: =+I39+O39+P39 -> 0 | T39: 0 | U39: 164 | X39: =+I39-T39 -> 0
A40: 177 | B40: CRANE; UNIFRAN; 2[t]; GANTRY TYPE | F40: MISS | G40: C1 | H40: 1994 | I40: =+'177'!R7 -> 2920 | J40: =+'177'!S7 -> 2920 | K40: =+I40-J40 -> 0 | M40: A | N40: =+I40-J40-K40 -> 0 | Q40: =+I40+O40+P40 -> 2920 | T40: 2920 | U40: 175 | X40: =+I40-T40 -> 0
...

Sheet MISC
A1: ABS EQUIPMENT LEASING INC.
A2: Select Equipment List
A3: Source: F 2009 Fixed Asset Summary
S4: Total | U4: Book
A5: Description | B5: Asset # | C5: Serial # | S5: Costs | T5: Depr. | U5: Value
H6: 110120 | I6: 333836.86 | J6: 129867.83
S7: =+C123 -> 5916533.8 | T7: =+-C157 -> 4699006.8 | U7: =+S7-T7 -> 1217527
B11: Asset # | D11: 220-221-288-222-175-178-176-207-223-224-213-214-225-226-227-289-229-230-231-232-233-258-234-235-177 | E11: box tables-pallets | F11: 229-237-238-239-251-1761-248 | G11: 237 | H11: 237-240-249-255 | I11: 240-249-259-261 | J11: 240-262-263-264-265 | K11: 260 | L11: 241-242-243-250-267 | M11: 242-268 | N11: 244 | O11: 245-270-271-272-517-269-211 | P11: 518-250-263-272-275-211 | Q11: 229-250-272 | S11: 265-279-519-280-281-282--283-284-715-720-716-701- | T11: 237-229-246-265-287 | U11: 721-tosh MPC
A13: Purchased Year Ending | C13: Total | D13: 1994 | E13: misc | F13: 1995 | G13: 1996 | H13: 1997 | I13: 1998 | J13: 1999 | K13: 2000 | L13: 2001 | M13: 2002 | N13: 2003 | O13: 2004 | P13: 2005 | Q13: 2006 | R13: 2007 | S13: 2008 | T13: 2009 | U13: 2010 | V13: 2011 | W13: 2012 | X13: 2013 | Y13: 2014 | Z13: 2015 | AA13: 2016 | AB13: 2017 | AC13: 2018 | AD13: 2019 | AE13: 2020 | AF13: 2021 | AG13: 2022 | AH13: 2023 | AI13: =AH13+1 -> 2024
A14: Purchases (Fiscal Yr.) | C14: =SUM(D14:AI14) -> -208035.43 | D14: 21496 | E14: 17030 | K14: 40931 | N14: 36715 | O14: 3476.43 | U14: 5769.72 | V14: 3478.42 | W14: =-180025-26162-10000-8140-27605-27268-32986-22378-6017 -> -340581 | X14: 3649
C15: =SUM(D15:AI15) -> 128213.22 | D15: 7000 | E15: 39150 | L15: 7099.74 | O15: 22818.58 | P15: 42022.9 | U15: 4447 | W15: 5175 | X15: 500
C16: =SUM(D16:AI16) -> 1310855.8 | D16: 7000 | F16: 110120 | G16: 333836.86 | H16: 129867.83 | T16: 8980 | W16: 707551.14 | X16: 13500
C17: =SUM(D17:AI17) -> -125550.72 | W17: -125550.72
A18: PAMA AT 130 MOVED FROM MISC SCH | B18: 237 | C18: =SUM(D18:AI18) -> -596304.69 | F18: =-F16 -> -110120 | G18: =-G16 -> -333836.86 | H18: =-H16 -> -129867.83 | T18: =-T16 -> -8980 | X18: =-X16 -> -13500
C19: =SUM(D19:AI19) -> 1891949.5 | D19: 1500 | F19: 16200 | H19: 1140792.8 | I19: 250593.26 | J19: 69321.32 | L19: 363556.65 | M19: 5943.1 | O19: 7902.78 | P19: 13112.15 | Q19: 6211.75 | T19: 17315.75 | X19: -500
C20: =SUM(D20:AI20) -> 335016.55 | D20: 121548.03 | F20: 15500 | H20: 11150 | I20: 32500 | J20: 11122.78 | L20: 38909 | M20: 104286.74
C21: =SUM(D21:AI21) -> 244233.35 | D21: 37606.01 | F21: 43637.34 | H21: 116990 | I21: 5500 | L21: 20500 | P21: 17500 | Q21: 2500
C22: =SUM(D22:AI22) -> 254704.09 | D22: 19282.42 | F22: 20169.44 | I22: 11500 | J22: 153099.23 | P22: 50653
C23: =SUM(D23:AI23) -> 53756.54 | D23: 10000 | F23: 7500 | J23: 36256.54
C24: =SUM(D24:AI24) -> 19882.42 | D24: 2166 | J24: 3687.1 | S24: 11690.14 | T24: 2339.18
C25: =SUM(D25:AI25) -> 48723.87 | D25: 7476.83 | L25: 11500 | O25: 13352.04 | P25: 6395 | S25: 10000
C26: =SUM(D26:AI26) -> 41558.8 | D26: 8000 | O26: 8402.8 | S26: 25156
C27: =SUM(D27:AI27) -> 34600.79 | D27: 5997 | O27: 3350 | P27: 3483.79 | S27: 21770
C28: =SUM(D28:AI28) -> 299438.57 | D28: 97200 | F28: 182234.12 | Q28: 3072.86 | T28: 16931.59
C29: =SUM(D29:AI29) -> 43000 | D29: 28000 | S29: 15000
C30: =SUM(D30:AI30) -> 59749.1 | D30: 51205 | S30: 8544.1
C31: =SUM(D31:AI31) -> 18089.4 | D31: 14665.3 | S31: 3424.1
C32: =SUM(D32:AI32) -> 9360.26 | D32: 1250 | S32: 8110.26
C33: =SUM(D33:AI33) -> 350736.43 | D33: 339414.37 | S33: 11322.06
C34: =SUM(D34:AI34) -> 186786.15 | D34: 45000 | F34: 124932.61 | G34: 16853.54
C35: =SUM(D35:AI35) -> 4971.56 | D35: 4971.56
C36: =SUM(D36:AI36) -> 3420 | D36: 2920 | T36: 500
C37: =SUM(D37:AI37) -> 500 | T37: 500
C38: =SUM(D38:AI38) -> 37000 | T38: 37000
C39: =SUM(D39:AI39) -> 6580 | Y39: 6580
C40: =SUM(D40:AI40) -> 8500 | Y40: 8500
C41: =SUM(D41:AI41) -> 9108 | Y41: =9108 -> 9108
C42: =SUM(D42:AI42) -> 18370 | Y42: 18370
A43: Toshiba MPC 1" Angle Head | C43: =SUM(D43:AI43) -> 330 | Z43: 330
A44: Miss Plant 2 - 1490 General | C44: =SUM(D44:AI44) -> 149208.48 | Z44: 3900.68 | AG44: 120628.95 | AH44: 24678.85
...

Sheet 100
A1: ABS EQUIPMENT LEASING INC.
A2: Equipment List
A3: Source: Fixed Asset Summary
R4: Total | T4: Book
A5: Description | B5: Asset # | C5: Serial # | R5: Costs | S5: Depr. | T5: Value
A7: FORESTLINE #1 | B7: =+SUMMARY!A9 -> 100 | C7: 3051 | R7: =+C14 -> 1971035.5 | S7: =+-C49 -> 1971035.5 | T7: =+R7-S7 -> 0
A8: VECOMIL 563 5 AXIS CNC VERTICAL
A9: sn:3051
A11: Location: | B11: MISS | C11: 1495
A13: Purchased Year Ending | C13: Total | D13: 1994 | E13: 1995 | F13: 1996 | G13: 1997 | H13: 1998 | I13: 1999 | J13: 2000 | K13: 2001 | L13: 2002 | M13: 2003 | N13: 2004 | O13: =N13+1 -> 2005 | P13: =O13+1 -> 2006 | Q13: =P13+1 -> 2007 | R13: =Q13+1 -> 2008 | S13: =R13+1 -> 2009 | T13: =S13+1 -> 2010 | U13: =T13+1 -> 2011 | V13: =U13+1 -> 2012 | ... AH13: =AG13+1 -> 2024
A14: Purchases (Fiscal Yr.) | C14: =SUM(D14:AH14) -> 1971035.5 | D14: =+'Equip Review 032310'!G29 -> 0 | E14: =+'Equip Review 032310'!H29 -> 0 | F14: =+'Equip Review 032310'!I29 -> 0 | G14: =+'Equip Review 032310'!J29 -> 0 | H14: =+'Equip Review 032310'!K29 -> 0 | I14: =+'Equip Review 032310'!L29 -> 0 | J14: =+'Equip Review 032310'!M29 -> 0 | K14: =+'Equip Review 032310'!N29 -> 0 | ... M14: =+'Equip Review 032310'!P29 -> 0 | N14: =+'Equip Review 032310'!Q29/2 -> 235173.89 | O14: =+'Equip Review 032310'!R29/2 -> 36232.98 | P14: =+'Equip Review 032310'!S29/2 -> 48260.59 | Q14: =(+'Equip Review 032310'!T29)/2 -> 185222.12 | R14: =(+'Equip Review 032310'!U29+'Equip Review 032310'!V29)/2 -> 39565.04 | S14: =+'Equip Review 032310'!W29 -> 0 | U14: 33173 | V14: 440690.72 | W14: 37505.37 | X14: 902360.38 | Y14: 12851.4 | Z14: 0 | AA14: 0 | AB14: 0 | AC14: 0 | AD14: 0
A16: Depreciation | B16: 1994 | C16: =-SUM(D16:AH16) -> 0 | D16: =+D$14/7/2 -> 0
B17: =B16+1 -> 1995 | C17: =-SUM(D17:AH17) -> 0 | D17: =+D$14/7 -> 0 | E17: =+E$14/7/2 -> 0
B18: =B17+1 -> 1996 | C18: =-SUM(D18:AH18) -> 0 | D18: =+D17 -> 0 | E18: =+E$14/7 -> 0 | F18: =+F$14/7/2 -> 0
B19: =B18+1 -> 1997 | C19: =-SUM(D19:AH19) -> 0 | D19: =+D18 -> 0 | E19: =+E18 -> 0 | F19: =+F$14/7 -> 0 | G19: =+G$14/7/2 -> 0
B20: =B19+1 -> 1998 | C20: =-SUM(D20:AH20) -> 0 | D20: =+D19 -> 0 | E20: =+E19 -> 0 | F20: =+F19 -> 0 | G20: =+G$14/7 -> 0 | H20: =+H$14/7/2 -> 0
B21: =B20+1 -> 1999 | C21: =-SUM(D21:AH21) -> 0 | D21: =+D20 -> 0 | E21: =+E20 -> 0 | F21: =+F20 -> 0 | G21: =+G20 -> 0 | H21: =+H$14/7 -> 0 | I21: =+I$14/7/2 -> 0
B22: =B21+1 -> 2000 | C22: =-SUM(D22:AH22) -> 0 | D22: =+D21 -> 0 | E22: =+E21 -> 0 | F22: =+F21 -> 0 | G22: =+G21 -> 0 | H22: =+H21 -> 0 | I22: =+I$14/7 -> 0 | J22: =+J$14/7/2 -> 0
B23: =B22+1 -> 2001 | C23: =-SUM(D23:AH23) -> 0 | D23: =+D$14/7/2 -> 0 | E23: =+E22 -> 0 | F23: =+F22 -> 0 | G23: =+G22 -> 0 | H23: =+H22 -> 0 | I23: =+I22 -> 0 | J23: =+J$14/7 -> 0 | K23: =+K$14/7/2 -> 0
B24: =B23+1 -> 2002 | C24: =-SUM(D24:AH24) -> 0 | E24: =+E$14/7/2 -> 0 | F24: =+F23 -> 0 | G24: =+G23 -> 0 | H24: =+H23 -> 0 | I24: =+I23 -> 0 | J24: =+J23 -> 0 | K24: =+K$14/7 -> 0 | L24: =+L$14/7/2 -> 0
B25: =B24+1 -> 2003 | C25: =-SUM(D25:AH25) -> 0 | F25: =+F$14/7/2 -> 0 | G25: =+G24 -> 0 | H25: =+H24 -> 0 | I25: =+I24 -> 0 | J25: =+J24 -> 0 | K25: =+K24 -> 0 | L25: =+L$14/7 -> 0 | M25: =+M$14/7/2 -> 0
B26: =B25+1 -> 2004 | C26: =-SUM(D26:AH26) -> -16798.135 | G26: =+G$14/7/2 -> 0 | H26: =+H25 -> 0 | I26: =+I25 -> 0 | J26: =+J25 -> 0 | K26: =+K25 -> 0 | L26: =+L25 -> 0 | M26: =+M$14/7 -> 0 | N26: =+N$14/7/2 -> 16798.135
B27: =B26+1 -> 2005 | C27: =-SUM(D27:AH27) -> -36184.339 | H27: =+H$14/7/2 -> 0 | I27: =+I26 -> 0 | J27: =+J26 -> 0 | K27: =+K26 -> 0 | L27: =+L26 -> 0 | M27: =+M26 -> 0 | N27: =+N$14/7 -> 33596.269 | O27: =+O$14/7/2 -> 2588.07
B28: =B27+1 -> 2006 | C28: =-SUM(D28:AH28) -> -42219.594 | I28: =+I$14/7/2 -> 0 | J28: =+J27 -> 0 | K28: =+K27 -> 0 | L28: =+L27 -> 0 | M28: =+M27 -> 0 | N28: =+N27 -> 33596.269 | O28: =+O$14/7 -> 5176.14 | P28: =+P$14/7/2 -> 3447.185
B29: =B28+1 -> 2007 | C29: =-SUM(D29:AH29) -> -58896.931 | J29: =+J$14/7/2 -> 0 | K29: =+K28 -> 0 | L29: =+L28 -> 0 | M29: =+M28 -> 0 | N29: =+N28 -> 33596.269 | O29: =+O28 -> 5176.14 | P29: =+P$14/7 -> 6894.37 | Q29: =+Q$14/7/2 -> 13230.152
B30: =B29+1 -> 2008 | C30: =-SUM(D30:AH30) -> -74953.157 | K30: =+K$14/7/2 -> 0 | L30: =+L29 -> 0 | M30: =+M29 -> 0 | N30: =+N29 -> 33596.269 | O30: =+O29 -> 5176.14 | P30: =+P29 -> 6894.37 | Q30: =+Q$14/7 -> 26460.304 | R30: =+R$14/7/2 -> 2826.0743
B31: =B30+1 -> 2009 | C31: =-SUM(D31:AH31) -> -77779.231 | L31: =+L$14/7/2 -> 0 | M31: =+M30 -> 0 | N31: =+N30 -> 33596.269 | O31: =+O30 -> 5176.14 | P31: =+P30 -> 6894.37 | Q31: =+Q30 -> 26460.304 | R31: =+R$14/7 -> 5652.1486 | S31: =+S$14/7/2 -> 0
A32: To April 30th, 2010 | B32: =B31+1 -> 2010 | C32: =-SUM(D32:AH32) -> -77779.231 | M32: =+M$14/7/2 -> 0 | N32: =+N31 -> 33596.269 | O32: =+O31 -> 5176.14 | P32: =+P31 -> 6894.37 | Q32: =+Q31 -> 26460.304 | R32: =+R31 -> 5652.1486 | S32: =+S$14/7 -> 0 | T32: =+T$14/7/2 -> 0
B33: =B32+1 -> 2011 | C33: =-SUM(D33:AH33) -> -63350.597 | N33: =+N$14/7/2 -> 16798.135 | O33: =+O32 -> 5176.14 | P33: =+P32 -> 6894.37 | Q33: =+Q32 -> 26460.304 | R33: =+R32 -> 5652.1486 | S33: =+S32 -> 0 | T33: =+T$14/7 -> 0 | U33: =+U$14/7/2 -> 2369.5
B34: =B33+1 -> 2012 | C34: =-SUM(D34:AH34) -> -77811.801 | O34: =+O$14/7/2 -> 2588.07 | P34: =+P33 -> 6894.37 | Q34: =+Q33 -> 26460.304 | R34: =+R33 -> 5652.1486 | S34: =+S33 -> 0 | T34: =+T$14/7 -> 0 | U34: =+U$14/7 -> 4739 | V34: =+V$14/7/2 -> 31477.909
B35: =B34+1 -> 2013 | C35: =-SUM(D35:AH35) -> -105933.41 | P35: =P14/7/2 -> 3447.185 | Q35: =+Q34 -> 26460.304 | R35: =+R34 -> 5652.1486 | U35: =+U$14/7 -> 4739 | V35: =+V$14/7 -> 62955.817 | W35: =W14/7/2 -> 2678.955
B36: =B35+1 -> 2014 | C36: =-SUM(D36:AH36) -> -156389.34 | Q36: =Q14/7/2 -> 13230.152 | R36: =+R35 -> 5652.1486 | U36: =+U$14/7 -> 4739 | V36: =+V$14/7 -> 62955.817 | W36: =+W$14/7 -> 5357.91 | X36: =X14/7/2 -> 64454.313
B37: =B36+1 -> 2015 | C37: =-SUM(D37:AH37) -> -205705.38 | R37: =R14/7/2 -> 2826.0743 | U37: =+U$14/7 -> 4739 | V37: =+V$14/7 -> 62955.817 | W37: =+W$14/7 -> 5357.91 | X37: =$X$14/7 -> 128908.63 | Y37: =Y14/7/2 -> 917.95714
B38: =B37+1 -> 2016 | C38: =-SUM(D38:AH38) -> -203797.27 | U38: =+U$14/7 -> 4739 | V38: =+V$14/7 -> 62955.817 | W38: =+W$14/7 -> 5357.91 | X38: =$X$14/7 -> 128908.63 | Y38: =$Y$14/7 -> 1835.9143
B39: =B38+1 -> 2017 | C39: =-SUM(D39:AH39) -> -203797.27 | U39: =+U$14/7 -> 4739 | V39: =+V$14/7 -> 62955.817 | W39: =+W$14/7 -> 5357.91 | X39: =$X$14/7 -> 128908.63 | Y39: =$Y$14/7 -> 1835.9143
B40: =B39+1 -> 2018 | C40: =-SUM(D40:AH40) -> -201427.77 | U40: 2369.5 | V40: =+V$14/7 -> 62955.817 | W40: =+W$14/7 -> 5357.91 | X40: =$X$14/7 -> 128908.63 | Y40: =$Y$14/7 -> 1835.9143
B41: =B40+1 -> 2019 | C41: =-SUM(D41:AH41) -> -167580.36 | V41: =+V$14/7/2 -> 31477.909 | W41: =+W$14/7 -> 5357.91 | X41: =$X$14/7 -> 128908.63 | Y41: =$Y$14/7 -> 1835.9143 | AC41: =$AC$14/7/2 -> 0
B42: =B41+1 -> 2020 | C42: =-SUM(D42:AH42) -> -133423.49 | W42: =+W$14/7/2 -> 2678.955 | X42: =$X$14/7 -> 128908.63 | Y42: =$Y$14/7 -> 1835.9143 | AC42: =$AC$14/7 -> 0
B43: =B42+1 -> 2021 | C43: =-SUM(D43:AH43) -> -66290.227 | X43: =$X$14/7/2 -> 64454.313 | Y43: =$Y$14/7 -> 1835.9143
B44: =B43+1 -> 2022 | C44: =-SUM(D44:AH44) -> -917.95714 | Y44: =$Y$14/7/2 -> 917.95714
...

Sheet 101
A1: ABS EQUIPMENT LEASING INC.
A2: Equipment List
A3: Source: F 2009 Fixed Asset Summary
R4: Total | T4: Book
A5: Description | B5: Asset # | C5: Serial # | R5: Costs | S5: Depr. | T5: Value
A6: =+SUMMARY!B10 -> MONTI FT 50 TG ( PURCH - ALESA MONTI) | B6: =+SUMMARY!A10 -> 101 | C6: =+SUMMARY!D10 -> 293/05.95
A7: =+SUMMARY!C10 -> FT50TG | R7: =+C14 -> 970993.94 | S7: =+-C48 -> 825242.42 | T7: =+R7-S7 -> 145751.52
A8: PURCH - ALESA MONTI
A11: Location: | B11: =+SUMMARY!F10 -> MISS | C11: C2
A13: Purchased Year Ending | C13: Total | D13: 1994 | E13: 1995 | F13: 1996 | G13: 1997 | H13: 1998 | I13: 1999 | J13: 2000 | K13: 2001 | L13: 2002 | M13: 2003 | N13: 2004 | O13: =N13+1 -> 2005 | P13: =O13+1 -> 2006 | Q13: =P13+1 -> 2007 | R13: =Q13+1 -> 2008 | S13: =R13+1 -> 2009 | T13: =S13+1 -> 2010 | U13: =T13+1 -> 2011 | V13: =U13+1 -> 2012 | ... AH13: =AG13+1 -> 2024
A14: Purchases (Fiscal Yr.) | C14: =SUM(D14:AH14) -> 970993.94 | F14: 661741.31 | AD14: 62123.56 | AE14: 247129.07
A15: =IF(+C14-'Equip Review 032310'!Y29=0,"ok","check") -> check
A16: Depreciation | B16: 1994 | C16: =-SUM(D16:AH16) -> 0 | D16: =+D$14/7/2 -> 0
B17: =B16+1 -> 1995 | C17: =-SUM(D17:AH17) -> 0 | D17: =+D$14/7 -> 0 | E17: =+E$14/7/2 -> 0
B18: =B17+1 -> 1996 | C18: =-SUM(D18:AH18) -> -47267.236 | D18: =+D17 -> 0 | E18: =+E$14/7 -> 0 | F18: =+F$14/7/2 -> 47267.236
B19: =B18+1 -> 1997 | C19: =-SUM(D19:AH19) -> -94534.473 | D19: =+D18 -> 0 | E19: =+E18 -> 0 | F19: =+F$14/7 -> 94534.473 | G19: =+G$14/7/2 -> 0
B20: =B19+1 -> 1998 | C20: =-SUM(D20:AH20) -> -94534.473 | D20: =+D19 -> 0 | E20: =+E19 -> 0 | F20: =+F19 -> 94534.473 | G20: =+G$14/7 -> 0 | H20: =+H$14/7/2 -> 0
B21: =B20+1 -> 1999 | C21: =-SUM(D21:AH21) -> -94534.473 | D21: =+D20 -> 0 | E21: =+E20 -> 0 | F21: =+F20 -> 94534.473 | G21: =+G20 -> 0 | H21: =+H$14/7 -> 0 | I21: =+I$14/7/2 -> 0
B22: =B21+1 -> 2000 | C22: =-SUM(D22:AH22) -> -94534.473 | D22: =+D21 -> 0 | E22: =+E21 -> 0 | F22: =+F21 -> 94534.473 | G22: =+G21 -> 0 | H22: =+H21 -> 0 | I22: =+I$14/7 -> 0 | J22: =+J$14/7/2 -> 0
B23: =B22+1 -> 2001 | C23: =-SUM(D23:AH23) -> -94534.473 | D23: =+D$14/7/2 -> 0 | E23: =+E22 -> 0 | F23: =+F22 -> 94534.473 | G23: =+G22 -> 0 | H23: =+H22 -> 0 | I23: =+I22 -> 0 | J23: =+J$14/7 -> 0 | K23: =+K$14/7/2 -> 0
B24: =B23+1 -> 2002 | C24: =-SUM(D24:AH24) -> -94534.473 | E24: =+E$14/7/2 -> 0 | F24: =+F23 -> 94534.473 | G24: =+G23 -> 0 | H24: =+H23 -> 0 | I24: =+I23 -> 0 | J24: =+J23 -> 0 | K24: =+K$14/7 -> 0 | L24: =+L$14/7/2 -> 0
B25: =B24+1 -> 2003 | C25: =-SUM(D25:AH25) -> -47267.236 | F25: =+F$14/7/2 -> 47267.236 | G25: =+G24 -> 0 | H25: =+H24 -> 0 | I25: =+I24 -> 0 | J25: =+J24 -> 0 | K25: =+K24 -> 0 | L25: =+L$14/7 -> 0 | M25: =+M$14/7/2 -> 0
B26: =B25+1 -> 2004 | C26: =-SUM(D26:AH26) -> 0 | G26: =+G$14/7/2 -> 0 | H26: =+H25 -> 0 | I26: =+I25 -> 0 | J26: =+J25 -> 0 | K26: =+K25 -> 0 | L26: =+L25 -> 0 | M26: =+M$14/7 -> 0 | N26: =+N$14/7/2 -> 0
B27: =B26+1 -> 2005 | C27: =-SUM(D27:AH27) -> 0 | H27: =+H$14/7/2 -> 0 | I27: =+I26 -> 0 | J27: =+J26 -> 0 | K27: =+K26 -> 0 | L27: =+L26 -> 0 | M27: =+M26 -> 0 | N27: =+N$14/7 -> 0 | O27: =+O$14/7/2 -> 0
B28: =B27+1 -> 2006 | C28: =-SUM(D28:AH28) -> 0 | I28: =+I$14/7/2 -> 0 | J28: =+J27 -> 0 | K28: =+K27 -> 0 | L28: =+L27 -> 0 | M28: =+M27 -> 0 | N28: =+N27 -> 0 | O28: =+O$14/7 -> 0 | P28: =+P$14/7/2 -> 0
B29: =B28+1 -> 2007 | C29: =-SUM(D29:AH29) -> 0 | J29: =+J$14/7/2 -> 0 | K29: =+K28 -> 0 | L29: =+L28 -> 0 | M29: =+M28 -> 0 | N29: =+N28 -> 0 | O29: =+O28 -> 0 | P29: =+P$14/7 -> 0 | Q29: =+Q$14/7/2 -> 0
B30: =B29+1 -> 2008 | C30: =-SUM(D30:AH30) -> 0 | K30: =+K$14/7/2 -> 0 | L30: =+L29 -> 0 | M30: =+M29 -> 0 | N30: =+N29 -> 0 | O30: =+O29 -> 0 | P30: =+P29 -> 0 | Q30: =+Q$14/7 -> 0 | R30: =+R$14/7/2 -> 0
B31: =B30+1 -> 2009 | C31: =-SUM(D31:AH31) -> 0 | L31: =+L$14/7/2 -> 0 | M31: =+M30 -> 0 | N31: =+N30 -> 0 | O31: =+O30 -> 0 | P31: =+P30 -> 0 | Q31: =+Q30 -> 0 | R31: =+R$14/7 -> 0 | S31: =+S$14/7/2 -> 0
A32: To April 30th, 2010 | B32: =B31+1 -> 2010 | C32: =-SUM(D32:AH32) -> 0 | M32: =+M$14/7/2 -> 0 | N32: =+N31 -> 0 | O32: =+O31 -> 0 | P32: =+P31 -> 0 | Q32: =+Q31 -> 0 | R32: =+R31 -> 0 | S32: =+S$14/7 -> 0 | T32: =+T$14/7/2 -> 0
B33: =B32+1 -> 2011 | C33: =-SUM(D33:AH33) -> 0 | N33: =+N$14/7/2 -> 0 | O33: =+O32 -> 0 | P33: =+P32 -> 0 | Q33: =+Q32 -> 0 | R33: =+R32 -> 0 | S33: =+S32 -> 0 | T33: =+T$14/7 -> 0 | U33: =+U$14/7/2 -> 0
B34: =B33+1 -> 2012 | C34: =-SUM(D34:AH34) -> 0 | Q34: =+Q33 -> 0 | R34: =+R33 -> 0 | S34: =+S33 -> 0 | T34: =+T$14/7 -> 0 | U34: =+U$14/7 -> 0 | V34: =+V$14/7/2 -> 0
B35: =B34+1 -> 2013 | C35: =-SUM(D35:AH35) -> 0
B36: =B35+1 -> 2014 | C36: =-SUM(D36:AH36) -> 0
B37: =B36+1 -> 2015 | C37: =-SUM(D37:AH37) -> 0
B38: =B37+1 -> 2016 | C38: =-SUM(D38:AH38) -> 0
B39: =B38+1 -> 2017 | C39: =-SUM(D39:AH39) -> 0
B40: =B39+1 -> 2018 | C40: =-SUM(D40:AH40) -> 0
B41: =B40+1 -> 2019 | C41: =-SUM(D41:AH41) -> 0
B42: =B41+1 -> 2020 | C42: =-SUM(D42:AH42) -> -4437.3971 | AD42: =$AD$14/7/2 -> 4437.3971
B43: =B42+1 -> 2021 | C43: =-SUM(D43:AH43) -> -26526.871 | AD43: =$AD$14/7 -> 8874.7943 | AE43: =$AE$14/7/2 -> 17652.076
...

Sheet 102
A1: ABS EQUIPMENT LEASING INC.
A2: Equipment List
A3: Source: F 2009 Fixed Asset Summary
R4: Total | T4: Book
A5: Description | B5: Asset # | C5: Serial # | R5: Costs | S5: Depr. | T5: Value
A6: FORESTLINE #2 | B6: 102
A7: FORESTLINE RETROFIT | C7: 3052 | R7: =+C14 -> 560665.7 | S7: =+-C46 -> 560665.7 | T7: =+R7-S7 -> 0
A11: Location: | B11: HAM
A13: Purchased Year Ending | C13: Total | D13: 1994 | E13: 1995 | F13: 1996 | G13: 1997 | H13: 1998 | I13: 1999 | J13: 2000 | K13: 2001 | L13: 2002 | M13: 2003 | N13: 2004 | O13: 2005 | P13: 2006 | Q13: 2007 | R13: 2008 | S13: 2009 | T13: 2010 | U13: 2011 | V13: 2012 | W13: 2013 | X13: 2014 | Y13: 2015 | Z13: 2016 | AA13: 2017 | AB13: 2018 | AC13: 2019
A14: Purchases (Fiscal Yr.) | C14: =SUM(D14:Y14) -> 560665.7 | I14: 0 | L14: 0 | N14: ='100'!N14 -> 235173.89 | O14: ='100'!O14 -> 36232.98 | P14: ='100'!P14 -> 48260.59 | Q14: ='100'!Q14 -> 185222.12 | R14: ='100'!R14 -> 39565.04 | Y14: 16211.08
A15: =IF(+C14-'Equip Review 032310'!Y29=0,"ok","check") -> check
A16: Depreciation | B16: 1994 | C16: =-SUM(D16:Y16) -> 0 | D16: =+D$14/7/2 -> 0
B17: 1995 | C17: =-SUM(D17:Y17) -> 0 | D17: =+D$14/7 -> 0 | E17: =+E$14/7/2 -> 0
B18: 1996 | C18: =-SUM(D18:Y18) -> 0 | D18: =+D17 -> 0 | E18: =+E$14/7 -> 0 | F18: =+F$14/7/2 -> 0
B19: 1997 | C19: =-SUM(D19:Y19) -> 0 | D19: =+D18 -> 0 | E19: =+E18 -> 0 | F19: =+F$14/7 -> 0 | G19: =+G$14/7/2 -> 0
B20: 1998 | C20: =-SUM(D20:Y20) -> 0 | D20: =+D19 -> 0 | E20: =+E19 -> 0 | F20: =+F19 -> 0 | G20: =+G$14/7 -> 0 | H20: =+H$14/7/2 -> 0
B21: 1999 | C21: =-SUM(D21:Y21) -> 0 | D21: =+D20 -> 0 | E21: =+E20 -> 0 | F21: =+F20 -> 0 | G21: =+G20 -> 0 | H21: =+H$14/7 -> 0 | I21: =+I$14/7/2 -> 0
B22: 2000 | C22: =-SUM(D22:Y22) -> 0 | D22: =+D21 -> 0 | E22: =+E21 -> 0 | F22: =+F21 -> 0 | G22: =+G21 -> 0 | H22: =+H21 -> 0 | I22: =+I$14/7 -> 0 | J22: =+J$14/7/2 -> 0
B23: 2001 | C23: =-SUM(D23:Y23) -> 0 | D23: =+D$14/7/2 -> 0 | E23: =+E22 -> 0 | F23: =+F22 -> 0 | G23: =+G22 -> 0 | H23: =+H22 -> 0 | I23: =+I22 -> 0 | J23: =+J$14/7 -> 0 | K23: =+K$14/7/2 -> 0
B24: 2002 | C24: =-SUM(D24:Y24) -> 0 | E24: =+E$14/7/2 -> 0 | F24: =+F23 -> 0 | G24: =+G23 -> 0 | H24: =+H23 -> 0 | I24: =+I23 -> 0 | J24: =+J23 -> 0 | K24: =+K$14/7 -> 0 | L24: =+L$14/7/2 -> 0
B25: 2003 | C25: =-SUM(D25:Y25) -> 0 | F25: =+F$14/7/2 -> 0 | G25: =+G24 -> 0 | H25: =+H24 -> 0 | I25: =+I24 -> 0 | J25: =+J24 -> 0 | K25: =+K24 -> 0 | L25: =+L$14/7 -> 0 | M25: =+M$14/7/2 -> 0
B26: 2004 | C26: =-SUM(D26:Y26) -> -16798.135 | G26: =+G$14/7/2 -> 0 | H26: =+H25 -> 0 | I26: =+I25 -> 0 | J26: =+J25 -> 0 | K26: =+K25 -> 0 | L26: =+L25 -> 0 | M26: =+M$14/7 -> 0 | N26: =+N$14/7/2 -> 16798.135
B27: 2005 | C27: =-SUM(D27:Y27) -> -36184.339 | H27: =+H$14/7/2 -> 0 | I27: =+I26 -> 0 | J27: =+J26 -> 0 | K27: =+K26 -> 0 | L27: =+L26 -> 0 | M27: =+M26 -> 0 | N27: =+N$14/7 -> 33596.269 | O27: =+O$14/7/2 -> 2588.07
B28: 2006 | C28: =-SUM(D28:Y28) -> -42219.594 | I28: =+I$14/7/2 -> 0 | J28: =+J27 -> 0 | K28: =+K27 -> 0 | L28: =+L27 -> 0 | M28: =+M27 -> 0 | N28: =+N27 -> 33596.269 | O28: =+O$14/7 -> 5176.14 | P28: =+P$14/7/2 -> 3447.185
B29: 2007 | C29: =-SUM(D29:Y29) -> -58896.931 | J29: =+J$14/7/2 -> 0 | K29: =+K28 -> 0 | L29: =+L28 -> 0 | M29: =+M28 -> 0 | N29: =+N28 -> 33596.269 | O29: =+O28 -> 5176.14 | P29: =+P$14/7 -> 6894.37 | Q29: =+Q$14/7/2 -> 13230.152
B30: 2008 | C30: =-SUM(D30:Y30) -> -74953.157 | K30: =+K$14/7/2 -> 0 | L30: =+L29 -> 0 | M30: =+M29 -> 0 | N30: =+N29 -> 33596.269 | O30: =+O29 -> 5176.14 | P30: =+P29 -> 6894.37 | Q30: =+Q$14/7 -> 26460.304 | R30: =+R$14/7/2 -> 2826.0743
B31: 2009 | C31: =-SUM(D31:Y31) -> -77779.231 | L31: =+L$14/7/2 -> 0 | M31: =+M30 -> 0 | N31: =+N30 -> 33596.269 | O31: =+O30 -> 5176.14 | P31: =+P30 -> 6894.37 | Q31: =+Q30 -> 26460.304 | R31: =+R$14/7 -> 5652.1486 | S31: =+S$14/7/2 -> 0
A32: To April 30th, 2010 | B32: 2010 | C32: =-SUM(D32:Y32) -> -77779.231 | M32: =+M$14/7/2 -> 0 | N32: =+N31 -> 33596.269 | O32: =+O31 -> 5176.14 | P32: =+P31 -> 6894.37 | Q32: =+Q31 -> 26460.304 | R32: =+R31 -> 5652.1486 | S32: =+S$14/7 -> 0 | T32: =+T$14/7/2 -> 0
B33: 2011 | C33: =-SUM(D33:Y33) -> -60981.097 | N33: =+N$14/7/2 -> 16798.135 | O33: =+O32 -> 5176.14 | P33: =+P32 -> 6894.37 | Q33: =+Q32 -> 26460.304 | R33: =+R32 -> 5652.1486 | S33: =+S32 -> 0 | T33: =+T$14/7 -> 0 | U33: =+U$14/7/2 -> 0
B34: 2012 | C34: =-SUM(D34:Y34) -> -41594.892 | O34: =O14/7/2 -> 2588.07 | P34: =P14/7 -> 6894.37 | Q34: =+Q33 -> 26460.304 | R34: =+R33 -> 5652.1486 | S34: =+S33 -> 0 | T34: =+T$14/7 -> 0 | U34: =+U$14/7 -> 0 | V34: =+V$14/7/2 -> 0
B35: 2013 | C35: =-SUM(D35:Y35) -> -35559.637 | P35: =P14/7/2 -> 3447.185 | Q35: =Q14/7 -> 26460.304 | R35: =R14/7 -> 5652.1486 | W35: =W14/7/2 -> 0
B36: 2014 | C36: =-SUM(D36:Y36) -> -18882.3 | Q36: =Q14/7/2 -> 13230.152 | R36: =R14/7 -> 5652.1486 | W36: =W14/7 -> 0 | X36: =X14/7 -> 0
B37: 2015 | C37: =-SUM(D37:Y37) -> -3984.0086 | R37: =R14/7/2 -> 2826.0743 | Y37: =$Y$14/7/2 -> 1157.9343
B38: 2016 | C38: =-SUM(D38:Y38) -> -2315.8686 | Y38: =$Y$14/7 -> 2315.8686
B39: 2017 | C39: =-SUM(D39:Y39) -> -2315.8686 | Y39: =$Y$14/7 -> 2315.8686
B40: 2018 | C40: =-SUM(N40:AB40) -> -2315.8686 | Y40: =$Y$14/7 -> 2315.8686
B41: 2019 | C41: =-SUM(N41:AB41) -> -2315.8686 | Y41: =$Y$14/7 -> 2315.8686
B42: 2020 | C42: =-SUM(N42:AB42) -> -2315.8686 | Y42: =$Y$14/7 -> 2315.8686
B43: 2021 | C43: =-SUM(N43:AB43) -> -2315.8686 | Y43: =$Y$14/7 -> 2315.8686
B44: 2022 | C44: =-SUM(N44:AB44) -> -1157.9343 | Y44: =$Y$14/7/2 -> 1157.9343
...

Sheet 103
A1: ABS EQUIPMENT LEASING INC.
A2: Equipment List
A3: Source: F 2009 Fixed Asset Summary
R4: Total | T4: Book
A5: Description | B5: Asset # | C5: Serial # | R5: Costs | S5: Depr. | T5: Value
A6: =+SUMMARY!B12 -> PAMA SPEEDRAM # 3 INCL TBL | B6: =+SUMMARY!A12 -> 103 | C6: =+SUMMARY!D12 -> 33C-7168
A7: =+SUMMARY!C12 -> BONETTI RETROFIT | R7: =+C14 -> 3824420.5 | S7: =+-C48 -> 3802179.5 | T7: =+R7-S7 -> 22241.024
A11: Location: | B11: =+SUMMARY!F12 -> BURL 1 | C11: A3
A13: Purchased Year Ending | C13: Total | D13: 1994 | E13: =D13+1 -> 1995 | F13: =E13+1 -> 1996 | G13: =F13+1 -> 1997 | H13: =G13+1 -> 1998 | I13: =H13+1 -> 1999 | J13: =I13+1 -> 2000 | K13: =J13+1 -> 2001 | L13: =K13+1 -> 2002 | ... AH13: =AG13+1 -> 2024
A14: Purchases (Fiscal Yr.) | C14: =SUM(D14:AH14) -> 3824420.5 | I14: 1284796.8 | L14: 11829.56 | O14: 10401.89 | W14: 77000 | Z14: =2412497.35+3943.04 -> 2416440.4 | AH14: 23951.88
A15: =IF(+C14-'Equip Review 032310'!Y29=0,"ok","check") -> check
A16: Depreciation | B16: 1994 | C16: =-SUM(D16:AH16) -> 0 | D16: =+D$14/7/2 -> 0
B17: =B16+1 -> 1995 | C17: =-SUM(D17:AH17) -> 0 | D17: =+D$14/7 -> 0 | E17: =+E$14/7/2 -> 0
B18: =B17+1 -> 1996 | C18: =-SUM(D18:AH18) -> 0 | D18: =+D17 -> 0 | E18: =+E$14/7 -> 0 | F18: =+F$14/7/2 -> 0
B19: =B18+1 -> 1997 | C19: =-SUM(D19:AH19) -> 0 | D19: =+D18 -> 0 | E19: =+E18 -> 0 | F19: =+F$14/7 -> 0 | G19: =+G$14/7/2 -> 0
B20: =B19+1 -> 1998 | C20: =-SUM(D20:AH20) -> 0 | D20: =+D19 -> 0 | E20: =+E19 -> 0 | F20: =+F19 -> 0 | G20: =+G$14/7 -> 0 | H20: =+H$14/7/2 -> 0
B21: =B20+1 -> 1999 | C21: =-SUM(D21:AH21) -> -91771.202 | D21: =+D20 -> 0 | E21: =+E20 -> 0 | F21: =+F20 -> 0 | G21: =+G20 -> 0 | H21: =+H$14/7 -> 0 | I21: =+I$14/7/2 -> 91771.202
B22: =B21+1 -> 2000 | C22: =-SUM(D22:AH22) -> -183542.4 | D22: =+D21 -> 0 | E22: =+E21 -> 0 | F22: =+F21 -> 0 | G22: =+G21 -> 0 | H22: =+H21 -> 0 | I22: =+I$14/7 -> 183542.4 | J22: =+J$14/7/2 -> 0
B23: =B22+1 -> 2001 | C23: =-SUM(D23:AH23) -> -183542.4 | D23: =+D$14/7/2 -> 0 | E23: =+E22 -> 0 | F23: =+F22 -> 0 | G23: =+G22 -> 0 | H23: =+H22 -> 0 | I23: =+I22 -> 183542.4 | J23: =+J$14/7 -> 0 | K23: =+K$14/7/2 -> 0
B24: =B23+1 -> 2002 | C24: =-SUM(D24:AH24) -> -184387.37 | E24: =+E$14/7/2 -> 0 | F24: =+F23 -> 0 | G24: =+G23 -> 0 | H24: =+H23 -> 0 | I24: =+I23 -> 183542.4 | J24: =+J23 -> 0 | K24: =+K$14/7 -> 0 | L24: =+L$14/7/2 -> 844.96857
B25: =B24+1 -> 2003 | C25: =-SUM(D25:AH25) -> -185232.34 | F25: =+F$14/7/2 -> 0 | G25: =+G24 -> 0 | H25: =+H24 -> 0 | I25: =+I24 -> 183542.4 | J25: =+J24 -> 0 | K25: =+K24 -> 0 | L25: =+L$14/7 -> 1689.9371 | M25: =+M$14/7/2 -> 0
B26: =B25+1 -> 2004 | C26: =-SUM(D26:AH26) -> -185232.34 | G26: =+G$14/7/2 -> 0 | H26: =+H25 -> 0 | I26: =+I25 -> 183542.4 | J26: =+J25 -> 0 | K26: =+K25 -> 0 | L26: =+L25 -> 1689.9371 | M26: =+M$14/7 -> 0 | N26: =+N$14/7/2 -> 0
B27: =B26+1 -> 2005 | C27: =-SUM(D27:AH27) -> -185975.33 | H27: =+H$14/7/2 -> 0 | I27: =+I26 -> 183542.4 | J27: =+J26 -> 0 | K27: =+K26 -> 0 | L27: =+L26 -> 1689.9371 | M27: =+M26 -> 0 | N27: =+N$14/7 -> 0 | O27: =+O$14/7/2 -> 742.99214
B28: =B27+1 -> 2006 | C28: =-SUM(D28:AH28) -> -94947.124 | I28: =+I$14/7/2 -> 91771.202 | J28: =+J27 -> 0 | K28: =+K27 -> 0 | L28: =+L27 -> 1689.9371 | M28: =+M27 -> 0 | N28: =+N27 -> 0 | O28: =+O$14/7 -> 1485.9843 | P28: =+P$14/7/2 -> 0
B29: =B28+1 -> 2007 | C29: =-SUM(D29:AH29) -> -3175.9214 | J29: =+J$14/7/2 -> 0 | K29: =+K28 -> 0 | L29: =+L28 -> 1689.9371 | M29: =+M28 -> 0 | N29: =+N28 -> 0 | O29: =+O28 -> 1485.9843 | P29: =+P$14/7 -> 0 | Q29: =+Q$14/7/2 -> 0
B30: =B29+1 -> 2008 | C30: =-SUM(D30:AH30) -> -3175.9214 | K30: =+K$14/7/2 -> 0 | L30: =+L29 -> 1689.9371 | M30: =+M29 -> 0 | N30: =+N29 -> 0 | O30: =+O29 -> 1485.9843 | P30: =+P29 -> 0 | Q30: =+Q$14/7 -> 0 | R30: =+R$14/7/2 -> 0
B31: =B30+1 -> 2009 | C31: =-SUM(D31:AH31) -> -2330.9529 | L31: =+L$14/7/2 -> 844.96857 | M31: =+M30 -> 0 | N31: =+N30 -> 0 | O31: =+O30 -> 1485.9843 | P31: =+P30 -> 0 | Q31: =+Q30 -> 0 | R31: =+R$14/7 -> 0 | S31: =+S$14/7/2 -> 0
A32: To April 30th, 2010 | B32: =B31+1 -> 2010 | C32: =-SUM(D32:AH32) -> -1485.9843 | M32: =+M$14/7/2 -> 0 | N32: =+N31 -> 0 | O32: =+O31 -> 1485.9843 | P32: =+P31 -> 0 | Q32: =+Q31 -> 0 | R32: =+R31 -> 0 | S32: =+S$14/7 -> 0 | T32: =+T$14/7/2 -> 0
B33: =B32+1 -> 2011 | C33: =-SUM(D33:AH33) -> -1485.9843 | N33: =+N$14/7/2 -> 0 | O33: =+O32 -> 1485.9843 | P33: =+P32 -> 0 | Q33: =+Q32 -> 0 | R33: =+R32 -> 0 | S33: =+S32 -> 0 | T33: =+T$14/7 -> 0 | U33: =+U$14/7/2 -> 0
B34: =B33+1 -> 2012 | C34: =-SUM(D34:AH34) -> -743 | O34: 743 | Q34: =+Q33 -> 0 | R34: =+R33 -> 0 | S34: =+S33 -> 0 | T34: =+T$14/7 -> 0 | U34: =+U$14/7 -> 0 | V34: =+V$14/7/2 -> 0
B35: =B34+1 -> 2013 | C35: =-SUM(D35:AH35) -> -5500 | W35: =$W$14/7/2 -> 5500
B36: =B35+1 -> 2014 | C36: =-SUM(D36:AH36) -> -11000 | W36: =$W$14/7 -> 11000
B37: =B36+1 -> 2015 | C37: =-SUM(D37:AH37) -> -11000 | W37: =$W$14/7 -> 11000 | Y37: =Y14/7/2 -> 0
B38: =B37+1 -> 2016 | C38: =-SUM(D38:AH38) -> -183602.89 | W38: =$W$14/7 -> 11000 | Z38: =$Z$14/7/2 -> 172602.89
B39: =B38+1 -> 2017 | C39: =-SUM(D39:AH39) -> -356205.77 | W39: =$W$14/7 -> 11000 | Z39: =$Z$14/7 -> 345205.77
B40: =B39+1 -> 2018 | C40: =-SUM(D40:AH40) -> -356205.77 | W40: =$W$14/7 -> 11000 | Z40: =$Z$14/7 -> 345205.77
B41: =B40+1 -> 2019 | C41: =-SUM(D41:AH41) -> -356205.77 | W41: =$W$14/7 -> 11000 | Z41: =$Z$14/7 -> 345205.77
B42: =B41+1 -> 2020 | C42: =-SUM(D42:AH42) -> -350705.77 | W42: =$W$14/7/2 -> 5500 | Z42: =$Z$14/7 -> 345205.77
B43: =B42+1 -> 2021 | C43: =-SUM(D43:AH43) -> -345205.77 | Z43: =$Z$14/7 -> 345205.77
B44: =B43+1 -> 2022 | C44: =-SUM(D44:AH44) -> -345205.77 | Z44: =$Z$14/7 -> 345205.77
...

Sheet 104
A1: ABS EQUIPMENT LEASING INC.
A2: Equipment List
A3: Source: F 2009 Fixed Asset Summary
R4: Total | T4: Book
A5: Description | B5: Asset # | C5: Serial # | R5: Costs | S5: Depr. | T5: Value
A6: =+SUMMARY!B13 -> PAMA CENTER 110 PO 113295 | B6: =+SUMMARY!A13 -> 104 | C6: =+SUMMARY!D13 -> 7357
A7: =+SUMMARY!C13 -> 5 AXIS | R7: =+C14 -> 2069204.1 | S7: =+-C49 -> 2069204.1 | T7: =+R7-S7 -> 0
A11: Location: | B11: =+SUMMARY!F13 -> JL | C11: C3
A13: Purchased Year Ending | C13: Total | D13: 1994 | E13: 1995 | F13: 1996 | G13: 1997 | H13: 1998 | I13: 1999 | J13: 2000 | K13: 2001 | L13: 2002 | M13: 2003 | N13: 2004 | O13: =N13+1 -> 2005 | P13: =O13+1 -> 2006 | Q13: =P13+1 -> 2007 | R13: =Q13+1 -> 2008 | S13: =R13+1 -> 2009 | T13: =S13+1 -> 2010 | U13: =T13+1 -> 2011 | V13: =U13+1 -> 2012 | ... AH13: =AG13+1 -> 2024
A14: Purchases (Fiscal Yr.) | C14: =SUM(D14:AH14) -> 2069204.1 | D14: 326318.29 | E14: 79857.13 | F14: 177640.13 | J14: 70800 | K14: 129218.27 | X14: 0 | Y14: =426317.04+940375.06 -> 1366692.1 | AA14: -81321.82
A15: =IF(+C14-'Equip Review 032310'!Y29=0,"ok","check") -> check
A16: Depreciation | B16: 1994 | C16: =-SUM(D16:AH16) -> -23308.449 | D16: =+D$14/7/2 -> 23308.449
B17: =B16+1 -> 1995 | C17: =-SUM(D17:AH17) -> -52320.979 | D17: =+D$14/7 -> 46616.899 | E17: =+E$14/7/2 -> 5704.0807
B18: =B17+1 -> 1996 | C18: =-SUM(D18:AH18) -> -70713.641 | D18: =+D17 -> 46616.899 | E18: =+E$14/7 -> 11408.161 | F18: =+F$14/7/2 -> 12688.581
B19: =B18+1 -> 1997 | C19: =-SUM(D19:AH19) -> -83402.221 | D19: =+D18 -> 46616.899 | E19: =+E18 -> 11408.161 | F19: =+F$14/7 -> 25377.161 | G19: =+G$14/7/2 -> 0
B20: =B19+1 -> 1998 | C20: =-SUM(D20:AH20) -> -83402.221 | D20: =+D19 -> 46616.899 | E20: =+E19 -> 11408.161 | F20: =+F19 -> 25377.161 | G20: =+G$14/7 -> 0 | H20: =+H$14/7/2 -> 0
B21: =B20+1 -> 1999 | C21: =-SUM(D21:AH21) -> -83402.221 | D21: =+D20 -> 46616.899 | E21: =+E20 -> 11408.161 | F21: =+F20 -> 25377.161 | G21: =+G20 -> 0 | H21: =+H$14/7 -> 0 | I21: =+I$14/7/2 -> 0
B22: =B21+1 -> 2000 | C22: =-SUM(D22:AH22) -> -88459.364 | D22: =+D21 -> 46616.899 | E22: =+E21 -> 11408.161 | F22: =+F21 -> 25377.161 | G22: =+G21 -> 0 | H22: =+H21 -> 0 | I22: =+I$14/7 -> 0 | J22: =+J$14/7/2 -> 5057.1429
